[I 2025-02-20 12:15:40,137] A new study created in RDB with name: NODE_Allstate_Claims
Traceback (most recent call last):
  File "/home/mburu/miniconda3/envs/Test4Node/lib/python3.8/site-packages/sqlalchemy/engine/base.py", line 1136, in _commit_impl
    self.engine.dialect.do_commit(self.connection)
  File "/home/mburu/miniconda3/envs/Test4Node/lib/python3.8/site-packages/sqlalchemy/engine/default.py", line 695, in do_commit
    dbapi_connection.commit()
sqlite3.OperationalError: disk I/O error

The above exception was the direct cause of the following exception:

Traceback (most recent call last):
  File "/home/mburu/.local/lib/python3.8/site-packages/optuna/storages/_rdb/storage.py", line 81, in _create_scoped_session
    session.commit()
  File "/home/mburu/miniconda3/envs/Test4Node/lib/python3.8/site-packages/sqlalchemy/orm/session.py", line 1969, in commit
    trans.commit(_to_root=True)
  File "<string>", line 2, in commit
  File "/home/mburu/miniconda3/envs/Test4Node/lib/python3.8/site-packages/sqlalchemy/orm/state_changes.py", line 139, in _go
    ret_value = fn(self, *arg, **kw)
  File "/home/mburu/miniconda3/envs/Test4Node/lib/python3.8/site-packages/sqlalchemy/orm/session.py", line 1263, in commit
    trans.commit()
  File "/home/mburu/miniconda3/envs/Test4Node/lib/python3.8/site-packages/sqlalchemy/engine/base.py", line 2620, in commit
    self._do_commit()
  File "/home/mburu/miniconda3/envs/Test4Node/lib/python3.8/site-packages/sqlalchemy/engine/base.py", line 2725, in _do_commit
    self._connection_commit_impl()
  File "/home/mburu/miniconda3/envs/Test4Node/lib/python3.8/site-packages/sqlalchemy/engine/base.py", line 2696, in _connection_commit_impl
    self.connection._commit_impl()
  File "/home/mburu/miniconda3/envs/Test4Node/lib/python3.8/site-packages/sqlalchemy/engine/base.py", line 1138, in _commit_impl
    self._handle_dbapi_exception(e, None, None, None, None)
  File "/home/mburu/miniconda3/envs/Test4Node/lib/python3.8/site-packages/sqlalchemy/engine/base.py", line 2344, in _handle_dbapi_exception
    raise sqlalchemy_exception.with_traceback(exc_info[2]) from e
  File "/home/mburu/miniconda3/envs/Test4Node/lib/python3.8/site-packages/sqlalchemy/engine/base.py", line 1136, in _commit_impl
    self.engine.dialect.do_commit(self.connection)
  File "/home/mburu/miniconda3/envs/Test4Node/lib/python3.8/site-packages/sqlalchemy/engine/default.py", line 695, in do_commit
    dbapi_connection.commit()
sqlalchemy.exc.OperationalError: (sqlite3.OperationalError) disk I/O error
(Background on this error at: https://sqlalche.me/e/20/e3q8)

The above exception was the direct cause of the following exception:

Traceback (most recent call last):
  File "/home/mburu/.local/lib/python3.8/site-packages/optuna/study/_optimize.py", line 209, in _run_trial
    frozen_trial = _tell_with_warning(
  File "/home/mburu/.local/lib/python3.8/site-packages/optuna/study/_tell.py", line 183, in _tell_with_warning
    study._storage.set_trial_state_values(frozen_trial._trial_id, state, values)
  File "/home/mburu/.local/lib/python3.8/site-packages/optuna/storages/_cached_storage.py", line 187, in set_trial_state_values
    return self._backend.set_trial_state_values(trial_id, state=state, values=values)
  File "/home/mburu/.local/lib/python3.8/site-packages/optuna/storages/_rdb/storage.py", line 661, in set_trial_state_values
    trial.datetime_complete = datetime.now()
  File "/home/mburu/miniconda3/envs/Test4Node/lib/python3.8/contextlib.py", line 120, in __exit__
    next(self.gen)
  File "/home/mburu/.local/lib/python3.8/site-packages/optuna/storages/_rdb/storage.py", line 98, in _create_scoped_session
    raise optuna.exceptions.StorageInternalError(message) from e
optuna.exceptions.StorageInternalError: An exception is raised during the commit. This typically happens due to invalid data in the commit, e.g. exceeding max length. 

During handling of the above exception, another exception occurred:

Traceback (most recent call last):
  File "train.py", line 188, in <module>
    main(arguments)
  File "train.py", line 159, 