/var/spool/slurm/d/job809768/slurm_script: line 11: activate: No such file or directory
No permission to create OpenML directory at /home/mburu/.config/openml! This can result in OpenML-Python not working properly.
Traceback (most recent call last):
  File "/home/mburu/miniconda3/envs/MasterThesis/lib/python3.10/site-packages/urllib3/connection.py", line 199, in _new_conn
    sock = connection.create_connection(
  File "/home/mburu/miniconda3/envs/MasterThesis/lib/python3.10/site-packages/urllib3/util/connection.py", line 60, in create_connection
    for res in socket.getaddrinfo(host, port, family, socket.SOCK_STREAM):
  File "/home/mburu/miniconda3/envs/MasterThesis/lib/python3.10/socket.py", line 967, in getaddrinfo
    for res in _socket.getaddrinfo(host, port, family, type, proto, flags):
socket.gaierror: [Errno -3] Temporary failure in name resolution

The above exception was the direct cause of the following exception:

Traceback (most recent call last):
  File "/home/mburu/miniconda3/envs/MasterThesis/lib/python3.10/site-packages/urllib3/connectionpool.py", line 789, in urlopen
    response = self._make_request(
  File "/home/mburu/miniconda3/envs/MasterThesis/lib/python3.10/site-packages/urllib3/connectionpool.py", line 490, in _make_request
    raise new_e
  File "/home/mburu/miniconda3/envs/MasterThesis/lib/python3.10/site-packages/urllib3/connectionpool.py", line 466, in _make_request
    self._validate_conn(conn)
  File "/home/mburu/miniconda3/envs/MasterThesis/lib/python3.10/site-packages/urllib3/connectionpool.py", line 1095, in _validate_conn
    conn.connect()
  File "/home/mburu/miniconda3/envs/MasterThesis/lib/python3.10/site-packages/urllib3/connection.py", line 693, in connect
    self.sock = sock = self._new_conn()
  File "/home/mburu/miniconda3/envs/MasterThesis/lib/python3.10/site-packages/urllib3/connection.py", line 206, in _new_conn
    raise NameResolutionError(self.host, self, e) from e
urllib3.exceptions.NameResolutionError: <urllib3.connection.HTTPSConnection object at 0x7fc7d4831210>: Failed to resolve 'www.openml.org' ([Errno -3] Temporary failure in name resolution)

The above exception was the direct cause of the following exception:

Traceback (most recent call last):
  File "/home/mburu/miniconda3/envs/MasterThesis/lib/python3.10/site-packages/requests/adapters.py", line 667, in send
    resp = conn.urlopen(
  File "/home/mburu/miniconda3/envs/MasterThesis/lib/python3.10/site-packages/urllib3/connectionpool.py", line 843, in urlopen
    retries = retries.increment(
  File "/home/mburu/miniconda3/envs/MasterThesis/lib/python3.10/site-packages/urllib3/util/retry.py", line 519, in increment
    raise MaxRetryError(_pool, url, reason) from reason  # type: ignore[arg-type]
urllib3.exceptions.MaxRetryError: HTTPSConnectionPool(host='www.openml.org', port=443): Max retries exceeded with url: /api/v1/study/269?api_key=1d638eca3385a3acd1fb477970ade481 (Caused by NameResolutionError("<urllib3.connection.HTTPSConnection object at 0x7fc7d4831210>: Failed to resolve 'www.openml.org' ([Errno -3] Temporary failure in name resolution)"))

During handling of the above exception, another exception occurred:

Traceback (most recent call last):
  File "/home/mburu/Master_Thesis/master-thesis-da/wrangling/data_download.py", line 26, in <module>
    benchmark_suite = study.get_suite(suite_id=269) ## OBJECT : OpenMLBenchmarkSuite
  File "/home/mburu/miniconda3/envs/MasterThesis/lib/python3.10/site-packages/openml/study/functions.py", line 35, in get_suite
    study = _get_study(suite_id, entity_type="task")
  File "/home/mburu/miniconda3/envs/MasterThesis/lib/python3.10/site-packages/openml/study/functions.py", line 82, in _get_study
    xml_string = openml._api_calls._perform_api_call(f"study/{id_}", "get")
  File "/home/mburu/miniconda3/envs/MasterThesis/lib/python3.10/site-packages/openml/_api_calls.py", line 117, in _perform_api_call
    response = __read_url(url, request_method, data)
  File "/home/mburu/miniconda3/envs/MasterThesis/lib/python3.10/site-packages/openml/_api_calls.py", line 337, in __read_url
    return _send_request(
  File "/home/mburu/miniconda3/envs/MasterThesis/lib/python3.10/site-packages/openml/_api_calls.py", line 436, in _send_request
    raise retry_raise_e
  File "/home/mburu/miniconda3/envs/MasterThesis/lib/python3.10/site-packages/openml/_api_calls.py", line 374, in _send_request
    response = session.get(url, params=data, headers=_HEADERS)
  File "/home/mburu/miniconda3/envs/MasterThesis/lib/python3.10/site-packages/requests/sessions.py", line 602, in get
    return self.request("GET", url, **kwargs)
  File "/home/mburu/miniconda3/envs/MasterThesis/lib/python3.10/site-packages/requests/sessions.py", line 589, in request
    resp = self.send(prep, **send_kwargs)
  File "/home/mburu/miniconda3/envs/MasterThesis/lib/python3.10/site-packages/requests/sessions.py", line 703, in send
    r = adapter.send(request, **kwargs)
  File "/home/mburu/miniconda3/envs/MasterThesis/lib/python3.10/site-packages/requests/adapters.py", line 700, in send
    raise ConnectionError(e, request=request)
requests.exceptions.ConnectionError: HTTPSConnectionPool(host='www.openml.org', port=443): Max retries exceeded with url: /api/v1/study/269?api_key=1d638eca3385a3acd1fb477970ade481 (Caused by NameResolutionError("<urllib3.connection.HTTPSConnection object at 0x7fc7d4831210>: Failed to resolve 'www.openml.org' ([Errno -3] Temporary failure in name resolution)"))
srun: error: stud-000: task 0: Exited with exit code 1
