

----------------------------------------------------------------------------
Training CatBoost Vesion 1 with Dataset: config/boston.yml 



----------------------------------------------------------------------------
Namespace(batch_size=128, cat_dims=None, cat_idx=None, config='config/boston.yml', data_parallel=False, dataset='Boston', direction='minimize', dropna_idx=None, early_stopping_rounds=20, epochs=1000, gpu_ids=[0, 1], logging_period=100, miss_cat_idx=None, miss_num_idx=None, model_name='CatBoost', n_trials=100, nominal_idx=[3], num_classes=1, num_features=13, num_splits=5, objective='regression', one_hot_encode=True, optimize_hyperparameters=True, ordinal_encode=False, ordinal_idx=None, scale=True, seed=221, shuffle=True, target_encode=False, use_gpu=True, val_batch_size=256)
Start hyperparameter optimization
Loading dataset Boston...
Dataset loaded!
(506, 13)
Scaling the data...
args.num_features: 14
New Shape: (506, 14)
A new study created in RDB with name: CatBoost_Boston
Trial 0 failed with parameters: {'learning_rate': 0.14483251897126667, 'max_depth': 8, 'l2_leaf_reg': 4.7559359212418055} because of the following error: CatBoostError("catboost/libs/train_lib/dir_helper.cpp:20: Can't create train working dir: output/CatBoost/Boston/catboost_info").
Traceback (most recent call last):
  File "/home/mburu/.local/lib/python3.8/site-packages/optuna/study/_optimize.py", line 197, in _run_trial
    value_or_values = func(trial)
  File "train.py", line 95, in __call__
    sc, time = cross_validation(model, self.X, self.y, self.args)
  File "train.py", line 41, in cross_validation
    loss_history, val_loss_history = curr_model.fit(X_train, y_train, X_test, y_test)  # X_val, y_val)
  File "/home/mburu/Master_Thesis/master-thesis-da/DNN_Trial/models/tree_models.py", line 112, in fit
    self.model.fit(X, y, eval_set=(X_val, y_val))
  File "/home/mburu/.local/lib/python3.8/site-packages/catboost/core.py", line 5299, in fit
    return self._fit(X, y, cat_features, None, None, None, sample_weight, None, None, None, None, baseline,
  File "/home/mburu/.local/lib/python3.8/site-packages/catboost/core.py", line 2037, in _fit
    self._train(
  File "/home/mburu/.local/lib/python3.8/site-packages/catboost/core.py", line 1464, in _train
    self._object._train(train_pool, test_pool, params, allow_clear_pool, init_model._object if init_model else None)
  File "_catboost.pyx", line 4393, in _catboost._CatBoost._train
  File "_catboost.pyx", line 4442, in _catboost._CatBoost._train
_catboost.CatBoostError: catboost/libs/train_lib/dir_helper.cpp:20: Can't create train working dir: output/CatBoost/Boston/catboost_info
Trial 0 failed with value None.


----------------------------------------------------------------------------
Training CatBoost Vesion 1 with Dataset: config/socmob.yml 



----------------------------------------------------------------------------
Namespace(batch_size=128, cat_dims=None, cat_idx=None, config='config/socmob.yml', data_parallel=False, dataset='Socmob', direction='minimize', dropna_idx=None, early_stopping_rounds=20, epochs=1000, gpu_ids=[0, 1], logging_period=100, miss_cat_idx=None, miss_num_idx=None, model_name='CatBoost', n_trials=100, nominal_idx=[0, 1, 2, 3], num_classes=1, num_features=5, num_splits=5, objective='regression', one_hot_encode=True, optimize_hyperparameters=True, ordinal_encode=False, ordinal_idx=None, scale=True, seed=221, shuffle=True, target_encode=False, use_gpu=True, val_batch_size=256)
Start hyperparameter optimization
Loading dataset Socmob...
Dataset loaded!
(1156, 5)
Scaling the data...
args.num_features: 39
New Shape: (1156, 39)
A new study created in RDB with name: CatBoost_Socmob
Trial 0 failed with parameters: {'learning_rate': 0.07038702207078341, 'max_depth': 2, 'l2_leaf_reg': 3.933042502738835} because of the following error: CatBoostError("catboost/libs/train_lib/dir_helper.cpp:20: Can't create train working dir: output/CatBoost/Socmob/catboost_info").
Traceback (most recent call last):
  File "/home/mburu/.local/lib/python3.8/site-packages/optuna/study/_optimize.py", line 197, in _run_trial
    value_or_values = func(trial)
  File "train.py", line 95, in __call__
    sc, time = cross_validation(model, self.X, self.y, self.args)
  File "train.py", line 41, in cross_validation
    loss_history, val_loss_history = curr_model.fit(X_train, y_train, X_test, y_test)  # X_val, y_val)
  File "/home/mburu/Master_Thesis/master-thesis-da/DNN_Trial/models/tree_models.py", line 112, in fit
    self.model.fit(X, y, eval_set=(X_val, y_val))
  File "/home/mburu/.local/lib/python3.8/site-packages/catboost/core.py", line 5299, in fit
    return self._fit(X, y, cat_features, None, None, None, sample_weight, None, None, None, None, baseline,
  File "/home/mburu/.local/lib/python3.8/site-packages/catboost/core.py", line 2037, in _fit
    self._train(
  File "/home/mburu/.local/lib/python3.8/site-packages/catboost/core.py", line 1464, in _train
    self._object._train(train_pool, test_pool, params, allow_clear_pool, init_model._object if init_model else None)
  File "_catboost.pyx", line 4393, in _catboost._CatBoost._train
  File "_catboost.pyx", line 4442, in _catboost._CatBoost._train
_catboost.CatBoostError: catboost/libs/train_lib/dir_helper.cpp:20: Can't create train working dir: output/CatBoost/Socmob/catboost_info
Trial 0 failed with value None.


----------------------------------------------------------------------------
Training CatBoost Vesion 1 with Dataset: config/sensory.yml 



----------------------------------------------------------------------------
Namespace(batch_size=128, cat_dims=None, cat_idx=None, config='config/sensory.yml', data_parallel=False, dataset='Sensory', direction='minimize', dropna_idx=None, early_stopping_rounds=20, epochs=1000, gpu_ids=[0, 1], logging_period=100, miss_cat_idx=None, miss_num_idx=None, model_name='CatBoost', n_trials=100, nominal_idx=[0, 1, 2, 3, 4, 5, 6, 7, 8, 9, 10], num_classes=1, num_features=11, num_splits=5, objective='regression', one_hot_encode=True, optimize_hyperparameters=True, ordinal_encode=False, ordinal_idx=None, scale=False, seed=221, shuffle=True, target_encode=False, use_gpu=True, val_batch_size=256)
Start hyperparameter optimization
Loading dataset Sensory...
Dataset loaded!
(576, 11)
args.num_features: 36
New Shape: (576, 36)
A new study created in RDB with name: CatBoost_Sensory
Trial 0 failed with parameters: {'learning_rate': 0.09142059160523999, 'max_depth': 11, 'l2_leaf_reg': 3.4190372841422882} because of the following error: CatBoostError("catboost/libs/train_lib/dir_helper.cpp:20: Can't create train working dir: output/CatBoost/Sensory/catboost_info").
Traceback (most recent call last):
  File "/home/mburu/.local/lib/python3.8/site-packages/optuna/study/_optimize.py", line 197, in _run_trial
    value_or_values = func(trial)
  File "train.py", line 95, in __call__
    sc, time = cross_validation(model, self.X, self.y, self.args)
  File "train.py", line 41, in cross_validation
    loss_history, val_loss_history = curr_model.fit(X_train, y_train, X_test, y_test)  # X_val, y_val)
  File "/home/mburu/Master_Thesis/master-thesis-da/DNN_Trial/models/tree_models.py", line 112, in fit
    self.model.fit(X, y, eval_set=(X_val, y_val))
  File "/home/mburu/.local/lib/python3.8/site-packages/catboost/core.py", line 5299, in fit
    return self._fit(X, y, cat_features, None, None, None, sample_weight, None, None, None, None, baseline,
  File "/home/mburu/.local/lib/python3.8/site-packages/catboost/core.py", line 2037, in _fit
    self._train(
  File "/home/mburu/.local/lib/python3.8/site-packages/catboost/core.py", line 1464, in _train
    self._object._train(train_pool, test_pool, params, allow_clear_pool, init_model._object if init_model else None)
  File "_catboost.pyx", line 4393, in _catboost._CatBoost._train
  File "_catboost.pyx", line 4442, in _catboost._CatBoost._train
_catboost.CatBoostError: catboost/libs/train_lib/dir_helper.cpp:20: Can't create train working dir: output/CatBoost/Sensory/catboost_info
Trial 0 failed with value None.


----------------------------------------------------------------------------
Training CatBoost Vesion 1 with Dataset: config/moneyball.yml 



----------------------------------------------------------------------------
Namespace(batch_size=128, cat_dims=None, cat_idx=None, config='config/moneyball.yml', data_parallel=False, dataset='Moneyball', direction='minimize', dropna_idx=[9, 10, 12, 13], early_stopping_rounds=20, epochs=1000, gpu_ids=[0, 1], logging_period=100, miss_cat_idx=None, miss_num_idx=None, model_name='CatBoost', n_trials=100, nominal_idx=[0, 1, 8], num_classes=1, num_features=14, num_splits=5, objective='regression', one_hot_encode=True, optimize_hyperparameters=True, ordinal_encode=False, ordinal_idx=None, scale=True, seed=221, shuffle=True, target_encode=False, use_gpu=True, val_batch_size=256)
Start hyperparameter optimization
Loading dataset Moneyball...
Dataset loaded!
(1232, 10)
Scaling the data...
args.num_features: 50
New Shape: (1232, 50)
A new study created in RDB with name: CatBoost_Moneyball
Trial 0 failed with parameters: {'learning_rate': 0.01457726106023375, 'max_depth': 10, 'l2_leaf_reg': 2.052277249157327} because of the following error: CatBoostError("catboost/libs/train_lib/dir_helper.cpp:20: Can't create train working dir: output/CatBoost/Moneyball/catboost_info").
Traceback (most recent call last):
  File "/home/mburu/.local/lib/python3.8/site-packages/optuna/study/_optimize.py", line 197, in _run_trial
    value_or_values = func(trial)
  File "train.py", line 95, in __call__
    sc, time = cross_validation(model, self.X, self.y, self.args)
  File "train.py", line 41, in cross_validation
    loss_history, val_loss_history = curr_model.fit(X_train, y_train, X_test, y_test)  # X_val, y_val)
  File "/home/mburu/Master_Thesis/master-thesis-da/DNN_Trial/models/tree_models.py", line 112, in fit
    self.model.fit(X, y, eval_set=(X_val, y_val))
  File "/home/mburu/.local/lib/python3.8/site-packages/catboost/core.py", line 5299, in fit
    return self._fit(X, y, cat_features, None, None, None, sample_weight, None, None, None, None, baseline,
  File "/home/mburu/.local/lib/python3.8/site-packages/catboost/core.py", line 2037, in _fit
    self._train(
  File "/home/mburu/.local/lib/python3.8/site-packages/catboost/core.py", line 1464, in _train
    self._object._train(train_pool, test_pool, params, allow_clear_pool, init_model._object if init_model else None)
  File "_catboost.pyx", line 4393, in _catboost._CatBoost._train
  File "_catboost.pyx", line 4442, in _catboost._CatBoost._train
_catboost.CatBoostError: catboost/libs/train_lib/dir_helper.cpp:20: Can't create train working dir: output/CatBoost/Moneyball/catboost_info
Trial 0 failed with value None.


----------------------------------------------------------------------------
Training CatBoost Vesion 1 with Dataset: config/black_friday.yml 



----------------------------------------------------------------------------
Namespace(batch_size=128, cat_dims=None, cat_idx=None, config='config/black_friday.yml', data_parallel=False, dataset='Black_Friday', direction='minimize', dropna_idx=None, early_stopping_rounds=20, epochs=1000, gpu_ids=[0, 1], logging_period=100, miss_cat_idx=None, miss_num_idx=None, model_name='CatBoost', n_trials=100, nominal_idx=[0, 2, 3, 5, 6, 7, 8], num_classes=1, num_features=9, num_splits=5, objective='regression', one_hot_encode=True, optimize_hyperparameters=True, ordinal_encode=True, ordinal_idx=[1], scale=True, seed=221, shuffle=True, target_encode=False, use_gpu=True, val_batch_size=256)
Start hyperparameter optimization
Loading dataset Black_Friday...
Dataset loaded!
(166821, 9)
Scaling the data...
args.num_features: 71
New Shape: (166821, 71)
A new study created in RDB with name: CatBoost_Black_Friday
Trial 0 failed with parameters: {'learning_rate': 0.015557151622622537, 'max_depth': 6, 'l2_leaf_reg': 0.6725662107575748} because of the following error: CatBoostError("catboost/libs/train_lib/dir_helper.cpp:20: Can't create train working dir: output/CatBoost/Black_Friday/catboost_info").
Traceback (most recent call last):
  File "/home/mburu/.local/lib/python3.8/site-packages/optuna/study/_optimize.py", line 197, in _run_trial
    value_or_values = func(trial)
  File "train.py", line 95, in __call__
    sc, time = cross_validation(model, self.X, self.y, self.args)
  File "train.py", line 41, in cross_validation
    loss_history, val_loss_history = curr_model.fit(X_train, y_train, X_test, y_test)  # X_val, y_val)
  File "/home/mburu/Master_Thesis/master-thesis-da/DNN_Trial/models/tree_models.py", line 112, in fit
    self.model.fit(X, y, eval_set=(X_val, y_val))
  File "/home/mburu/.local/lib/python3.8/site-packages/catboost/core.py", line 5299, in fit
    return self._fit(X, y, cat_features, None, None, None, sample_weight, None, None, None, None, baseline,
  File "/home/mburu/.local/lib/python3.8/site-packages/catboost/core.py", line 2037, in _fit
    self._train(
  File "/home/mburu/.local/lib/python3.8/site-packages/catboost/core.py", line 1464, in _train
    self._object._train(train_pool, test_pool, params, allow_clear_pool, init_model._object if init_model else None)
  File "_catboost.pyx", line 4393, in _catboost._CatBoost._train
  File "_catboost.pyx", line 4442, in _catboost._CatBoost._train
_catboost.CatBoostError: catboost/libs/train_lib/dir_helper.cpp:20: Can't create train working dir: output/CatBoost/Black_Friday/catboost_info
Trial 0 failed with value None.
