[I 2025-01-23 09:56:15,962] Using an existing study with name 'XGBoost_Boston' instead of creating a new one.
[W 2025-01-23 09:56:16,758] Trial 250 failed with parameters: {'max_depth': 3, 'alpha': 0.008409124286847003, 'lambda': 7.304566158975653e-05, 'eta': 0.07561861749602093} because of the following error: XGBoostError('[09:56:16] /workspace/src/c_api/../common/common.h:174: XGBoost version not compiled with GPU support.\nStack trace:\n  [bt] (0) /home/mburu/.local/lib/python3.8/site-packages/xgboost/lib/libxgboost.so(+0x170a4e) [0x7fec6139ea4e]\n  [bt] (1) /home/mburu/.local/lib/python3.8/site-packages/xgboost/lib/libxgboost.so(+0x170d11) [0x7fec6139ed11]\n  [bt] (2) /home/mburu/.local/lib/python3.8/site-packages/xgboost/lib/libxgboost.so(+0x4db3df) [0x7fec617093df]\n  [bt] (3) /home/mburu/.local/lib/python3.8/site-packages/xgboost/lib/libxgboost.so(+0x52f130) [0x7fec6175d130]\n  [bt] (4) /home/mburu/.local/lib/python3.8/site-packages/xgboost/lib/libxgboost.so(XGBoosterBoostedRounds+0x1d) [0x7fec612b54dd]\n  [bt] (5) /home/mburu/miniconda3/envs/TabSurvey2/lib/python3.8/lib-dynload/../../libffi.so.8(+0xa052) [0x7fec7aff2052]\n  [bt] (6) /home/mburu/miniconda3/envs/TabSurvey2/lib/python3.8/lib-dynload/../../libffi.so.8(+0x8925) [0x7fec7aff0925]\n  [bt] (7) /home/mburu/miniconda3/envs/TabSurvey2/lib/python3.8/lib-dynload/../../libffi.so.8(ffi_call+0xde) [0x7fec7aff106e]\n  [bt] (8) /home/mburu/miniconda3/envs/TabSurvey2/lib/python3.8/lib-dynload/_ctypes.cpython-38-x86_64-linux-gnu.so(_ctypes_callproc+0x31f) [0x7fec7b00c4af]\n\n').
Traceback (most recent call last):
  File "/home/mburu/.local/lib/python3.8/site-packages/optuna/study/_optimize.py", line 197, in _run_trial
    value_or_values = func(trial)
  File "train.py", line 134, in __call__
    sc, time = cross_validation(model, self.X, self.y, self.args, visual=False)
  File "train.py", line 46, in cross_validation
    loss_history, val_loss_history = curr_model.fit(X_train, y_train, X_test, y_test)  # X_val, y_val)
  File "/home/mburu/Master_Thesis/master-thesis-da/DNN_Trial/models/tree_models.py", line 51, in fit
    self.model = xgb.train(self.params, train, num_boost_round=self.args.epochs, evals=eval_list,
  File "/home/mburu/.local/lib/python3.8/site-packages/xgboost/core.py", line 738, in inner_f
    return func(**kwargs)
  File "/home/mburu/.local/lib/python3.8/site-packages/xgboost/training.py", line 176, in train
    bst = cb_container.before_training(bst)
  File "/home/mburu/.local/lib/python3.8/site-packages/xgboost/callback.py", line 179, in before_training
    model = c.before_training(model=model)
  File "/home/mburu/.local/lib/python3.8/site-packages/xgboost/callback.py", line 374, in before_training
    self.starting_round = model.num_boosted_rounds()
  File "/home/mburu/.local/lib/python3.8/site-packages/xgboost/core.py", line 2755, in num_boosted_rounds
    _check_call(_LIB.XGBoosterBoostedRounds(self.handle, ctypes.byref(rounds)))
  File "/home/mburu/.local/lib/python3.8/site-packages/xgboost/core.py", line 296, in _check_call
    raise XGBoostError(py_str(_LIB.XGBGetLastError()))
xgboost.core.XGBoostError: [09:56:16] /workspace/src/c_api/../common/common.h:174: XGBoost version not compiled with GPU support.
Stack trace:
  [bt] (0) /home/mburu/.local/lib/python3.8/site-packages/xgboost/lib/libxgboost.so(+0x170a4e) [0x7fec6139ea4e]
  [bt] (1) /home/mburu/.local/lib/python3.8/site-packages/xgboost/lib/libxgboost.so(+0x170d11) [0x7fec6139ed11]
  [bt] (2) /home/mburu/.local/lib/python3.8/site-packages/xgboost/lib/libxgboost.so(+0x4db3df) [0x7fec617093df]
  [bt] (3) /home/mburu/.local/lib/python3.8/site-packages/xgboost/lib/libxgboost.so(+0x52f130) [0x7fec6175d130]
  [bt] (4) /home/mburu/.local/lib/python3.8/site-packages/xgboost/lib/libxgboost.so(XGBoosterBoostedRounds+0x1d) [0x7fec612b54dd]
  [bt] (5) /home/mburu/miniconda3/envs/TabSurvey2/lib/python3.8/lib-dynload/../../libffi.so.8(+0xa052) [0x7fec7aff2052]
  [bt] (6) /home/mburu/miniconda3/envs/TabSurvey2/lib/python3.8/lib-dynload/../../libffi.so.8(+0x8925) [0x7fec7aff0925]
  [bt] (7) /home/mburu/miniconda3/envs/TabSurvey2/lib/python3.8/lib-dynload/../../libffi.so.8(ffi_call+0xde) [0x7fec7aff106e]
  [bt] (8) /home/mburu/miniconda3/envs/TabSurvey2/lib/python3.8/lib-dynload/_ctypes.cpython-38-x86_64-linux-gnu.so(_ctypes_callproc+0x31f) [0x7fec7b00c4af]


[W 2025-01-23 09:56:16,772] Trial 250 failed with value None.
Traceback (most recent call last):
  File "train.py", line 185, in <module>
    main(arguments)
  File "train.py", line 156, in main
    study.optimize(Objective(args, model_name, X, y), n_trials=args.n_trials)
  File "/home/mburu/.local/lib/python3.8/site-packages/optuna/study/study.py", line 475, in optimize
    _optimize(
  File "/home/mburu/.local/lib/python3.8/site-packages/optuna/study/_optimize.py", line 63, in _optimize
    _optimize_sequential(
  File "/home/mburu/.local/lib/python3.8/site-packages/optuna/study/_optimize.py", line 160, in _optimize_sequential
    frozen_trial = _run_trial(study, func, catch)
  File "/home/mburu/.local/lib/python3.8/site-packages/optuna/study/_optimize.py", line 248, in _run_trial
    raise func_err
  File "/home/mburu/.local/lib/python3.8/site-packages/optuna/study/_optimize.py", line 197, in _run_trial
    value_or_values = func(trial)
  File "train.py", line 134, in __call__
    sc, time = cross_validation(model, self.X, self.y, self.args, visual=False)
  File "train.py", line 46, in cross_validation
    loss_history, val_loss_history = curr_model.fit(X_train, y_train, X_test, y_test)  # X_val, y_val)
  File "/home/mburu/Master_Thesis/master-thesis-da/DNN_Trial/models/tree_models.py", line 51, in fit
    self.model = xgb.train(self.params, train, num_boost_round=self.args.epochs, evals=eval_list, 
  File "/home/mburu/.local/lib/python3.8/site-packages/xgboost/core.py", line 738, in inner_f
    return func(**kwargs)
  File "/home/mburu/.local/lib/python3.8/site-packages/xgboost/training.py", line 176, in train
    bst = cb_container.before_training(bst)
  File "/home/mburu/.local/lib/python3.8/site-packages/xgboost/callback.py", line 179, in before_training
    model = c.before_training(model=model)
  File "/home/mburu/.local/lib/python3.8/site-packages/xgboost/callback.py", line 374, in before_training
    self.starting_round = model.num_boosted_rounds()
  File "/home/mburu/.local/lib/python3.8/site-packages/xgboost/core.py", line 2755, in num_boosted_rounds
    _check_call(_LIB.XGBoosterBoostedRounds(self.handle, ctypes.byref(rounds)))
  File "/home/mburu/.local/lib/python3.8/site-packages/xgboost/core.py", line 296, in _check_call
    raise XGBoostError(py_str(_LIB.XGBGetLastError()))
xgboost.core.XGBoostError: [09:56:16] /workspace/src/c_api/../common/common.h:174: XGBoost version not compiled with GPU support.
Stack trace:
  [bt] (0) /home/mburu/.local/lib/python3.8/site-packages/xgboost/lib/libxgboost.so(+0x170a4e) [0x7fec6139ea4e]
  [bt] (1) /home/mburu/.local/lib/python3.8/site-packages/xgboost/lib/libxgboost.so(+0x170d11) [0x7fec6139ed11]
  [bt] (2) /home/mburu/.local/lib/python3.8/site-packages/xgboost/lib/libxgboost.so(+0x4db3df) [0x7fec617093df]
  [bt] (3) /home/mburu/.local/lib/python3.8/site-packages/xgboost/lib/libxgboost.so(+0x52f130) [0x7fec6175d130]
  [bt] (4) /home/mburu/.local/lib/python3.8/site-packages/xgboost/lib/libxgboost.so(XGBoosterBoostedRounds+0x1d) [0x7fec612b54dd]
  [bt] (5) /home/mburu/miniconda3/envs/TabSurvey2/lib/python3.8/lib-dynload/../../libffi.so.8(+0xa052) [0x7fec7aff2052]
  [bt] (6) /home/mburu/miniconda3/envs/TabSurvey2/lib/python3.8/lib-dynload/../../libffi.so.8(+0x8925) [0x7fec7aff0925]
  [bt] (7) /home/mburu/miniconda3/envs/TabSurvey2/lib/python3.8/lib-dynload/../../libffi.so.8(ffi_call+0xde) [0x7fec7aff106e]
  [bt] (8) /home/mburu/miniconda3/envs/TabSurvey2/lib/python3.8/lib-dynload/_ctypes.cpython-38-x86_64-linux-gnu.so(_ctypes_callproc+0x31f) [0x7fec7b00c4af]


srun: error: stud-000: task 0: Exited with exit code 1
[I 2025-01-23 09:56:21,148] Using an existing study with name 'XGBoost_Socmob' instead of creating a new one.
[W 2025-01-23 09:56:28,819] Trial 250 failed with parameters: {'max_depth': 8, 'alpha': 8.458177616973769e-05, 'lambda': 0.7014606596868784, 'eta': 0.22374234774853405} because of the following error: XGBoostError('[09:56:27] /workspace/src/c_api/../common/common.h:174: XGBoost version not compiled with GPU support.\nStack trace:\n  [bt] (0) /home/mburu/.local/lib/python3.8/site-packages/xgboost/lib/libxgboost.so(+0x170a4e) [0x7f1dc0c37a4e]\n  [bt] (1) /home/mburu/.local/lib/python3.8/site-packages/xgboost/lib/libxgboost.so(+0x170d11) [0x7f1dc0c37d11]\n  [bt] (2) /home/mburu/.local/lib/python3.8/site-packages/xgboost/lib/libxgboost.so(+0x4db3df) [0x7f1dc0fa23df]\n  [bt] (3) /home/mburu/.local/lib/python3.8/site-packages/xgboost/lib/libxgboost.so(+0x52f130) [0x7f1dc0ff6130]\n  [bt] (4) /home/mburu/.local/lib/python3.8/site-packages/xgboost/lib/libxgboost.so(XGBoosterBoostedRounds+0x1d) [0x7f1dc0b4e4dd]\n  [bt] (5) /home/mburu/miniconda3/envs/TabSurvey2/lib/python3.8/lib-dynload/../../libffi.so.8(+0xa052) [0x7f1dda88b052]\n  [bt] (6) /home/mburu/miniconda3/envs/TabSurvey2/lib/python3.8/lib-dynload/../../libffi.so.8(+0x8925) [0x7f1dda889925]\n  [bt] (7) /home/mburu/miniconda3/envs/TabSurvey2/lib/python3.8/lib-dynload/../../libffi.so.8(ffi_call+0xde) [0x7f1dda88a06e]\n  [bt] (8) /home/mburu/miniconda3/envs/TabSurvey2/lib/python3.8/lib-dynload/_ctypes.cpython-38-x86_64-linux-gnu.so(_ctypes_callproc+0x31f) [0x7f1dda8a54af]\n\n').
Traceback (most recent call last):
  File "/home/mburu/.local/lib/python3.8/site-packages/optuna/study/_optimize.py", line 197, in _run_trial
    value_or_values = func(trial)
  File "train.py", line 134, in __call__
    sc, time = cross_validation(model, self.X, self.y, self.args, visual=False)
  File "train.py", line 46, in cross_validation
    loss_history, val_loss_history = curr_model.fit(X_train, y_train, X_test, y_test)  # X_val, y_val)
  File "/home/mburu/Master_Thesis/master-thesis-da/DNN_Trial/models/tree_models.py", line 51, in fit
    self.model = xgb.train(self.params, train, num_boost_round=self.args.epochs, evals=eval_list,
  File "/home/mburu/.local/lib/python3.8/site-packages/xgboost/core.py", line 738, in inner_f
    return func(**kwargs)
  File "/home/mburu/.local/lib/python3.8/site-packages/xgboost/training.py", line 176, in train
    bst = cb_container.before_training(bst)
  File "/home/mburu/.local/lib/python3.8/site-packages/xgboost/callback.py", line 179, in before_training
    model = c.before_training(model=model)
  File "/home/mburu/.local/lib/python3.8/site-packages/xgboost/callback.py", line 374, in before_training
    self.starting_round = model.num_boosted_rounds()
  File "/home/mburu/.local/lib/python3.8/site-packages/xgboost/core.py", line 2755, in num_boosted_rounds
    _check_call(_LIB.XGBoosterBoostedRounds(self.handle, ctypes.byref(rounds)))
  File "/home/mburu/.local/lib/python3.8/site-packages/xgboost/core.py", line 296, in _check_call
    raise XGBoostError(py_str(_LIB.XGBGetLastError()))
xgboost.core.XGBoostError: [09:56:27] /workspace/src/c_api/../common/common.h:174: XGBoost version not compiled with GPU support.
Stack trace:
  [bt] (0) /home/mburu/.local/lib/python3.8/site-packages/xgboost/lib/libxgboost.so(+0x170a4e) [0x7f1dc0c37a4e]
  [bt] (1) /home/mburu/.local/lib/python3.8/site-packages/xgboost/lib/libxgboost.so(+0x170d11) [0x7f1dc0c37d11]
  [bt] (2) /home/mburu/.local/lib/python3.8/site-packages/xgboost/lib/libxgboost.so(+0x4db3df) [0x7f1dc0fa23df]
  [bt] (3) /home/mburu/.local/lib/python3.8/site-packages/xgboost/lib/libxgboost.so(+0x52f130) [0x7f1dc0ff6130]
  [bt] (4) /home/mburu/.local/lib/python3.8/site-packages/xgboost/lib/libxgboost.so(XGBoosterBoostedRounds+0x1d) [0x7f1dc0b4e4dd]
  [bt] (5) /home/mburu/miniconda3/envs/TabSurvey2/lib/python3.8/lib-dynload/../../libffi.so.8(+0xa052) [0x7f1dda88b052]
  [bt] (6) /home/mburu/miniconda3/envs/TabSurvey2/lib/python3.8/lib-dynload/../../libffi.so.8(+0x8925) [0x7f1dda889925]
  [bt] (7) /home/mburu/miniconda3/envs/TabSurvey2/lib/python3.8/lib-dynload/../../libffi.so.8(ffi_call+0xde) [0x7f1dda88a06e]
  [bt] (8) /home/mburu/miniconda3/envs/TabSurvey2/lib/python3.8/lib-dynload/_ctypes.cpython-38-x86_64-linux-gnu.so(_ctypes_callproc+0x31f) [0x7f1dda8a54af]


[W 2025-01-23 09:56:28,985] Trial 250 failed with value None.
Traceback (most recent call last):
  File "train.py", line 185, in <module>
    main(arguments)
  File "train.py", line 156, in main
    study.optimize(Objective(args, model_name, X, y), n_trials=args.n_trials)
  File "/home/mburu/.local/lib/python3.8/site-packages/optuna/study/study.py", line 475, in optimize
    _optimize(
  File "/home/mburu/.local/lib/python3.8/site-packages/optuna/study/_optimize.py", line 63, in _optimize
    _optimize_sequential(
  File "/home/mburu/.local/lib/python3.8/site-packages/optuna/study/_optimize.py", line 160, in _optimize_sequential
    frozen_trial = _run_trial(study, func, catch)
  File "/home/mburu/.local/lib/python3.8/site-packages/optuna/study/_optimize.py", line 248, in _run_trial
    raise func_err
  File "/home/mburu/.local/lib/python3.8/site-packages/optuna/study/_optimize.py", line 197, in _run_trial
    value_or_values = func(trial)
  File "train.py", line 134, in __call__
    sc, time = cross_validation(model, self.X, self.y, self.args, visual=False)
  File "train.py", line 46, in cross_validation
    loss_history, val_loss_history = curr_model.fit(X_train, y_train, X_test, y_test)  # X_val, y_val)
  File "/home/mburu/Master_Thesis/master-thesis-da/DNN_Trial/models/tree_models.py", line 51, in fit
    self.model = xgb.train(self.params, train, num_boost_round=self.args.epochs, evals=eval_list, 
  File "/home/mburu/.local/lib/python3.8/site-packages/xgboost/core.py", line 738, in inner_f
    return func(**kwargs)
  File "/home/mburu/.local/lib/python3.8/site-packages/xgboost/training.py", line 176, in train
    bst = cb_container.before_training(bst)
  File "/home/mburu/.local/lib/python3.8/site-packages/xgboost/callback.py", line 179, in before_training
    model = c.before_training(model=model)
  File "/home/mburu/.local/lib/python3.8/site-packages/xgboost/callback.py", line 374, in before_training
    self.starting_round = model.num_boosted_rounds()
  File "/home/mburu/.local/lib/python3.8/site-packages/xgboost/core.py", line 2755, in num_boosted_rounds
    _check_call(_LIB.XGBoosterBoostedRounds(self.handle, ctypes.byref(rounds)))
  File "/home/mburu/.local/lib/python3.8/site-packages/xgboost/core.py", line 296, in _check_call
    raise XGBoostError(py_str(_LIB.XGBGetLastError()))
xgboost.core.XGBoostError: [09:56:27] /workspace/src/c_api/../common/common.h:174: XGBoost version not compiled with GPU support.
Stack trace:
  [bt] (0) /home/mburu/.local/lib/python3.8/site-packages/xgboost/lib/libxgboost.so(+0x170a4e) [0x7f1dc0c37a4e]
  [bt] (1) /home/mburu/.local/lib/python3.8/site-packages/xgboost/lib/libxgboost.so(+0x170d11) [0x7f1dc0c37d11]
  [bt] (2) /home/mburu/.local/lib/python3.8/site-packages/xgboost/lib/libxgboost.so(+0x4db3df) [0x7f1dc0fa23df]
  [bt] (3) /home/mburu/.local/lib/python3.8/site-packages/xgboost/lib/libxgboost.so(+0x52f130) [0x7f1dc0ff6130]
  [bt] (4) /home/mburu/.local/lib/python3.8/site-packages/xgboost/lib/libxgboost.so(XGBoosterBoostedRounds+0x1d) [0x7f1dc0b4e4dd]
  [bt] (5) /home/mburu/miniconda3/envs/TabSurvey2/lib/python3.8/lib-dynload/../../libffi.so.8(+0xa052) [0x7f1dda88b052]
  [bt] (6) /home/mburu/miniconda3/envs/TabSurvey2/lib/python3.8/lib-dynload/../../libffi.so.8(+0x8925) [0x7f1dda889925]
  [bt] (7) /home/mburu/miniconda3/envs/TabSurvey2/lib/python3.8/lib-dynload/../../libffi.so.8(ffi_call+0xde) [0x7f1dda88a06e]
  [bt] (8) /home/mburu/miniconda3/envs/TabSurvey2/lib/python3.8/lib-dynload/_ctypes.cpython-38-x86_64-linux-gnu.so(_ctypes_callproc+0x31f) [0x7f1dda8a54af]


srun: error: stud-000: task 0: Exited with exit code 1
[I 2025-01-23 09:57:16,586] Using an existing study with name 'XGBoost_Sensory' instead of creating a new one.
[W 2025-01-23 09:57:18,454] Trial 201 failed with parameters: {'max_depth': 3, 'alpha': 1.405243344332809e-08, 'lambda': 3.165798931234532e-08, 'eta': 0.024044066485621948} because of the following error: TypeError("expected a sequence of integers or a single integer, got '11.0'").
Traceback (most recent call last):
  File "/home/mburu/.local/lib/python3.8/site-packages/optuna/study/_optimize.py", line 197, in _run_trial
    value_or_values = func(trial)
  File "train.py", line 134, in __call__
    sc, time = cross_validation(model, self.X, self.y, self.args, visual=False)
  File "train.py", line 46, in cross_validation
    loss_history, val_loss_history = curr_model.fit(X_train, y_train, X_test, y_test)  # X_val, y_val)
  File "/home/mburu/Master_Thesis/master-thesis-da/DNN_Trial/models/tree_models.py", line 43, in fit
    feature_types = self.feature_types().tolist()
  File "/home/mburu/Master_Thesis/master-thesis-da/DNN_Trial/models/tree_models.py", line 74, in feature_types
    feat_types = np.empty(np.max(np.concatenate([self.args.cat_idx, self.args.num_idx])) + 1, dtype=object)
TypeError: expected a sequence of integers or a single integer, got '11.0'
[W 2025-01-23 09:57:18,455] Trial 201 failed with value None.
Traceback (most recent call last):
  File "train.py", line 185, in <module>
    main(arguments)
  File "train.py", line 156, in main
    study.optimize(Objective(args, model_name, X, y), n_trials=args.n_trials)
  File "/home/mburu/.local/lib/python3.8/site-packages/optuna/study/study.py", line 475, in optimize
    _optimize(
  File "/home/mburu/.local/lib/python3.8/site-packages/optuna/study/_optimize.py", line 63, in _optimize
    _optimize_sequential(
  File "/home/mburu/.local/lib/python3.8/site-packages/optuna/study/_optimize.py", line 160, in _optimize_sequential
    frozen_trial = _run_trial(study, func, catch)
  File "/home/mburu/.local/lib/python3.8/site-packages/optuna/study/_optimize.py", line 248, in _run_trial
    raise func_err
  File "/home/mburu/.local/lib/python3.8/site-packages/optuna/study/_optimize.py", line 197, in _run_trial
    value_or_values = func(trial)
  File "train.py", line 134, in __call__
    sc, time = cross_validation(model, self.X, self.y, self.args, visual=False)
  File "train.py", line 46, in cross_validation
    loss_history, val_loss_history = curr_model.fit(X_train, y_train, X_test, y_test)  # X_val, y_val)
  File "/home/mburu/Master_Thesis/master-thesis-da/DNN_Trial/models/tree_models.py", line 43, in fit
    feature_types = self.feature_types().tolist()
  File "/home/mburu/Master_Thesis/master-thesis-da/DNN_Trial/models/tree_models.py", line 74, in feature_types
    feat_types = np.empty(np.max(np.concatenate([self.args.cat_idx, self.args.num_idx])) + 1, dtype=object)
TypeError: expected a sequence of integers or a single integer, got '11.0'
srun: error: stud-000: task 0: Exited with exit code 1
[I 2025-01-23 09:57:23,216] Using an existing study with name 'XGBoost_Moneyball' instead of creating a new one.
[W 2025-01-23 09:57:23,575] Trial 250 failed with parameters: {'max_depth': 2, 'alpha': 9.410571319135369e-07, 'lambda': 0.32998715318827515, 'eta': 0.050778482112561224} because of the following error: XGBoostError('[09:57:23] /workspace/src/c_api/../common/common.h:174: XGBoost version not compiled with GPU support.\nStack trace:\n  [bt] (0) /home/mburu/.local/lib/python3.8/site-packages/xgboost/lib/libxgboost.so(+0x170a4e) [0x7fe31ba07a4e]\n  [bt] (1) /home/mburu/.local/lib/python3.8/site-packages/xgboost/lib/libxgboost.so(+0x170d11) [0x7fe31ba07d11]\n  [bt] (2) /home/mburu/.local/lib/python3.8/site-packages/xgboost/lib/libxgboost.so(+0x4db3df) [0x7fe31bd723df]\n  [bt] (3) /home/mburu/.local/lib/python3.8/site-packages/xgboost/lib/libxgboost.so(+0x52f130) [0x7fe31bdc6130]\n  [bt] (4) /home/mburu/.local/lib/python3.8/site-packages/xgboost/lib/libxgboost.so(XGBoosterBoostedRounds+0x1d) [0x7fe31b91e4dd]\n  [bt] (5) /home/mburu/miniconda3/envs/TabSurvey2/lib/python3.8/lib-dynload/../../libffi.so.8(+0xa052) [0x7fe33569b052]\n  [bt] (6) /home/mburu/miniconda3/envs/TabSurvey2/lib/python3.8/lib-dynload/../../libffi.so.8(+0x8925) [0x7fe335699925]\n  [bt] (7) /home/mburu/miniconda3/envs/TabSurvey2/lib/python3.8/lib-dynload/../../libffi.so.8(ffi_call+0xde) [0x7fe33569a06e]\n  [bt] (8) /home/mburu/miniconda3/envs/TabSurvey2/lib/python3.8/lib-dynload/_ctypes.cpython-38-x86_64-linux-gnu.so(_ctypes_callproc+0x31f) [0x7fe3356b54af]\n\n').
Traceback (most recent call last):
  File "/home/mburu/.local/lib/python3.8/site-packages/optuna/study/_optimize.py", line 197, in _run_trial
    value_or_values = func(trial)
  File "train.py", line 134, in __call__
    sc, time = cross_validation(model, self.X, self.y, self.args, visual=False)
  File "train.py", line 46, in cross_validation
    loss_history, val_loss_history = curr_model.fit(X_train, y_train, X_test, y_test)  # X_val, y_val)
  File "/home/mburu/Master_Thesis/master-thesis-da/DNN_Trial/models/tree_models.py", line 51, in fit
    self.model = xgb.train(self.params, train, num_boost_round=self.args.epochs, evals=eval_list,
  File "/home/mburu/.local/lib/python3.8/site-packages/xgboost/core.py", line 738, in inner_f
    return func(**kwargs)
  File "/home/mburu/.local/lib/python3.8/site-packages/xgboost/training.py", line 176, in train
    bst = cb_container.before_training(bst)
  File "/home/mburu/.local/lib/python3.8/site-packages/xgboost/callback.py", line 179, in before_training
    model = c.before_training(model=model)
  File "/home/mburu/.local/lib/python3.8/site-packages/xgboost/callback.py", line 374, in before_training
    self.starting_round = model.num_boosted_rounds()
  File "/home/mburu/.local/lib/python3.8/site-packages/xgboost/core.py", line 2755, in num_boosted_rounds
    _check_call(_LIB.XGBoosterBoostedRounds(self.handle, ctypes.byref(rounds)))
  File "/home/mburu/.local/lib/python3.8/site-packages/xgboost/core.py", line 296, in _check_call
    raise XGBoostError(py_str(_LIB.XGBGetLastError()))
xgboost.core.XGBoostError: [09:57:23] /workspace/src/c_api/../common/common.h:174: XGBoost version not compiled with GPU support.
Stack trace:
  [bt] (0) /home/mburu/.local/lib/python3.8/site-packages/xgboost/lib/libxgboost.so(+0x170a4e) [0x7fe31ba07a4e]
  [bt] (1) /home/mburu/.local/lib/python3.8/site-packages/xgboost/lib/libxgboost.so(+0x170d11) [0x7fe31ba07d11]
  [bt] (2) /home/mburu/.local/lib/python3.8/site-packages/xgboost/lib/libxgboost.so(+0x4db3df) [0x7fe31bd723df]
  [bt] (3) /home/mburu/.local/lib/python3.8/site-packages/xgboost/lib/libxgboost.so(+0x52f130) [0x7fe31bdc6130]
  [bt] (4) /home/mburu/.local/lib/python3.8/site-packages/xgboost/lib/libxgboost.so(XGBoosterBoostedRounds+0x1d) [0x7fe31b91e4dd]
  [bt] (5) /home/mburu/miniconda3/envs/TabSurvey2/lib/python3.8/lib-dynload/../../libffi.so.8(+0xa052) [0x7fe33569b052]
  [bt] (6) /home/mburu/miniconda3/envs/TabSurvey2/lib/python3.8/lib-dynload/../../libffi.so.8(+0x8925) [0x7fe335699925]
  [bt] (7) /home/mburu/miniconda3/envs/TabSurvey2/lib/python3.8/lib-dynload/../../libffi.so.8(ffi_call+0xde) [0x7fe33569a06e]
  [bt] (8) /home/mburu/miniconda3/envs/TabSurvey2/lib/python3.8/lib-dynload/_ctypes.cpython-38-x86_64-linux-gnu.so(_ctypes_callproc+0x31f) [0x7fe3356b54af]


[W 2025-01-23 09:57:23,577] Trial 250 failed with value None.
Traceback (most recent call last):
  File "train.py", line 185, in <module>
    main(arguments)
  File "train.py", line 156, in main
    study.optimize(Objective(args, model_name, X, y), n_trials=args.n_trials)
  File "/home/mburu/.local/lib/python3.8/site-packages/optuna/study/study.py", line 475, in optimize
    _optimize(
  File "/home/mburu/.local/lib/python3.8/site-packages/optuna/study/_optimize.py", line 63, in _optimize
    _optimize_sequential(
  File "/home/mburu/.local/lib/python3.8/site-packages/optuna/study/_optimize.py", line 160, in _optimize_sequential
    frozen_trial = _run_trial(study, func, catch)
  File "/home/mburu/.local/lib/python3.8/site-packages/optuna/study/_optimize.py", line 248, in _run_trial
    raise func_err
  File "/home/mburu/.local/lib/python3.8/site-packages/optuna/study/_optimize.py", line 197, in _run_trial
    value_or_values = func(trial)
  File "train.py", line 134, in __call__
    sc, time = cross_validation(model, self.X, self.y, self.args, visual=False)
  File "train.py", line 46, in cross_validation
    loss_history, val_loss_history = curr_model.fit(X_train, y_train, X_test, y_test)  # X_val, y_val)
  File "/home/mburu/Master_Thesis/master-thesis-da/DNN_Trial/models/tree_models.py", line 51, in fit
    self.model = xgb.train(self.params, train, num_boost_round=self.args.epochs, evals=eval_list, 
  File "/home/mburu/.local/lib/python3.8/site-packages/xgboost/core.py", line 738, in inner_f
    return func(**kwargs)
  File "/home/mburu/.local/lib/python3.8/site-packages/xgboost/training.py", line 176, in train
    bst = cb_container.before_training(bst)
  File "/home/mburu/.local/lib/python3.8/site-packages/xgboost/callback.py", line 179, in before_training
    model = c.before_training(model=model)
  File "/home/mburu/.local/lib/python3.8/site-packages/xgboost/callback.py", line 374, in before_training
    self.starting_round = model.num_boosted_rounds()
  File "/home/mburu/.local/lib/python3.8/site-packages/xgboost/core.py", line 2755, in num_boosted_rounds
    _check_call(_LIB.XGBoosterBoostedRounds(self.handle, ctypes.byref(rounds)))
  File "/home/mburu/.local/lib/python3.8/site-packages/xgboost/core.py", line 296, in _check_call
    raise XGBoostError(py_str(_LIB.XGBGetLastError()))
xgboost.core.XGBoostError: [09:57:23] /workspace/src/c_api/../common/common.h:174: XGBoost version not compiled with GPU support.
Stack trace:
  [bt] (0) /home/mburu/.local/lib/python3.8/site-packages/xgboost/lib/libxgboost.so(+0x170a4e) [0x7fe31ba07a4e]
  [bt] (1) /home/mburu/.local/lib/python3.8/site-packages/xgboost/lib/libxgboost.so(+0x170d11) [0x7fe31ba07d11]
  [bt] (2) /home/mburu/.local/lib/python3.8/site-packages/xgboost/lib/libxgboost.so(+0x4db3df) [0x7fe31bd723df]
  [bt] (3) /home/mburu/.local/lib/python3.8/site-packages/xgboost/lib/libxgboost.so(+0x52f130) [0x7fe31bdc6130]
  [bt] (4) /home/mburu/.local/lib/python3.8/site-packages/xgboost/lib/libxgboost.so(XGBoosterBoostedRounds+0x1d) [0x7fe31b91e4dd]
  [bt] (5) /home/mburu/miniconda3/envs/TabSurvey2/lib/python3.8/lib-dynload/../../libffi.so.8(+0xa052) [0x7fe33569b052]
  [bt] (6) /home/mburu/miniconda3/envs/TabSurvey2/lib/python3.8/lib-dynload/../../libffi.so.8(+0x8925) [0x7fe335699925]
  [bt] (7) /home/mburu/miniconda3/envs/TabSurvey2/lib/python3.8/lib-dynload/../../libffi.so.8(ffi_call+0xde) [0x7fe33569a06e]
  [bt] (8) /home/mburu/miniconda3/envs/TabSurvey2/lib/python3.8/lib-dynload/_ctypes.cpython-38-x86_64-linux-gnu.so(_ctypes_callproc+0x31f) [0x7fe3356b54af]


srun: error: stud-000: task 0: Exited with exit code 1
[I 2025-01-23 09:57:54,513] Using an existing study with name 'XGBoost_Black_Friday' instead of creating a new one.
[W 2025-01-23 09:57:56,126] Trial 250 failed with parameters: {'max_depth': 7, 'alpha': 1.8675031578847007e-05, 'lambda': 0.7977259412128078, 'eta': 0.15302297894808148} because of the following error: XGBoostError('[09:57:56] /workspace/src/c_api/../common/common.h:174: XGBoost version not compiled with GPU support.\nStack trace:\n  [bt] (0) /home/mburu/.local/lib/python3.8/site-packages/xgboost/lib/libxgboost.so(+0x170a4e) [0x7fb442f2ba4e]\n  [bt] (1) /home/mburu/.local/lib/python3.8/site-packages/xgboost/lib/libxgboost.so(+0x170d11) [0x7fb442f2bd11]\n  [bt] (2) /home/mburu/.local/lib/python3.8/site-packages/xgboost/lib/libxgboost.so(+0x4db3df) [0x7fb4432963df]\n  [bt] (3) /home/mburu/.local/lib/python3.8/site-packages/xgboost/lib/libxgboost.so(+0x52f130) [0x7fb4432ea130]\n  [bt] (4) /home/mburu/.local/lib/python3.8/site-packages/xgboost/lib/libxgboost.so(XGBoosterBoostedRounds+0x1d) [0x7fb442e424dd]\n  [bt] (5) /home/mburu/miniconda3/envs/TabSurvey2/lib/python3.8/lib-dynload/../../libffi.so.8(+0xa052) [0x7fb45d0d7052]\n  [bt] (6) /home/mburu/miniconda3/envs/TabSurvey2/lib/python3.8/lib-dynload/../../libffi.so.8(+0x8925) [0x7fb45d0d5925]\n  [bt] (7) /home/mburu/miniconda3/envs/TabSurvey2/lib/python3.8/lib-dynload/../../libffi.so.8(ffi_call+0xde) [0x7fb45d0d606e]\n  [bt] (8) /home/mburu/miniconda3/envs/TabSurvey2/lib/python3.8/lib-dynload/_ctypes.cpython-38-x86_64-linux-gnu.so(_ctypes_callproc+0x31f) [0x7fb45d0f14af]\n\n').
Traceback (most recent call last):
  File "/home/mburu/.local/lib/python3.8/site-packages/optuna/study/_optimize.py", line 197, in _run_trial
    value_or_values = func(trial)
  File "train.py", line 134, in __call__
    sc, time = cross_validation(model, self.X, self.y, self.args, visual=False)
  File "train.py", line 46, in cross_validation
    loss_history, val_loss_history = curr_model.fit(X_train, y_train, X_test, y_test)  # X_val, y_val)
  File "/home/mburu/Master_Thesis/master-thesis-da/DNN_Trial/models/tree_models.py", line 51, in fit
    self.model = xgb.train(self.params, train, num_boost_round=self.args.epochs, evals=eval_list,
  File "/home/mburu/.local/lib/python3.8/site-packages/xgboost/core.py", line 738, in inner_f
    return func(**kwargs)
  File "/home/mburu/.local/lib/python3.8/site-packages/xgboost/training.py", line 176, in train
    bst = cb_container.before_training(bst)
  File "/home/mburu/.local/lib/python3.8/site-packages/xgboost/callback.py", line 179, in before_training
    model = c.before_training(model=model)
  File "/home/mburu/.local/lib/python3.8/site-packages/xgboost/callback.py", line 374, in before_training
    self.starting_round = model.num_boosted_rounds()
  File "/home/mburu/.local/lib/python3.8/site-packages/xgboost/core.py", line 2755, in num_boosted_rounds
    _check_call(_LIB.XGBoosterBoostedRounds(self.handle, ctypes.byref(rounds)))
  File "/home/mburu/.local/lib/python3.8/site-packages/xgboost/core.py", line 296, in _check_call
    raise XGBoostError(py_str(_LIB.XGBGetLastError()))
xgboost.core.XGBoostError: [09:57:56] /workspace/src/c_api/../common/common.h:174: XGBoost version not compiled with GPU support.
Stack trace:
  [bt] (0) /home/mburu/.local/lib/python3.8/site-packages/xgboost/lib/libxgboost.so(+0x170a4e) [0x7fb442f2ba4e]
  [bt] (1) /home/mburu/.local/lib/python3.8/site-packages/xgboost/lib/libxgboost.so(+0x170d11) [0x7fb442f2bd11]
  [bt] (2) /home/mburu/.local/lib/python3.8/site-packages/xgboost/lib/libxgboost.so(+0x4db3df) [0x7fb4432963df]
  [bt] (3) /home/mburu/.local/lib/python3.8/site-packages/xgboost/lib/libxgboost.so(+0x52f130) [0x7fb4432ea130]
  [bt] (4) /home/mburu/.local/lib/python3.8/site-packages/xgboost/lib/libxgboost.so(XGBoosterBoostedRounds+0x1d) [0x7fb442e424dd]
  [bt] (5) /home/mburu/miniconda3/envs/TabSurvey2/lib/python3.8/lib-dynload/../../libffi.so.8(+0xa052) [0x7fb45d0d7052]
  [bt] (6) /home/mburu/miniconda3/envs/TabSurvey2/lib/python3.8/lib-dynload/../../libffi.so.8(+0x8925) [0x7fb45d0d5925]
  [bt] (7) /home/mburu/miniconda3/envs/TabSurvey2/lib/python3.8/lib-dynload/../../libffi.so.8(ffi_call+0xde) [0x7fb45d0d606e]
  [bt] (8) /home/mburu/miniconda3/envs/TabSurvey2/lib/python3.8/lib-dynload/_ctypes.cpython-38-x86_64-linux-gnu.so(_ctypes_callproc+0x31f) [0x7fb45d0f14af]


[W 2025-01-23 09:57:56,129] Trial 250 failed with value None.
Traceback (most recent call last):
  File "train.py", line 185, in <module>
    main(arguments)
  File "train.py", line 156, in main
    study.optimize(Objective(args, model_name, X, y), n_trials=args.n_trials)
  File "/home/mburu/.local/lib/python3.8/site-packages/optuna/study/study.py", line 475, in optimize
    _optimize(
  File "/home/mburu/.local/lib/python3.8/site-packages/optuna/study/_optimize.py", line 63, in _optimize
    _optimize_sequential(
  File "/home/mburu/.local/lib/python3.8/site-packages/optuna/study/_optimize.py", line 160, in _optimize_sequential
    frozen_trial = _run_trial(study, func, catch)
  File "/home/mburu/.local/lib/python3.8/site-packages/optuna/study/_optimize.py", line 248, in _run_trial
    raise func_err
  File "/home/mburu/.local/lib/python3.8/site-packages/optuna/study/_optimize.py", line 197, in _run_trial
    value_or_values = func(trial)
  File "train.py", line 134, in __call__
    sc, time = cross_validation(model, self.X, self.y, self.args, visual=False)
  File "train.py", line 46, in cross_validation
    loss_history, val_loss_history = curr_model.fit(X_train, y_train, X_test, y_test)  # X_val, y_val)
  File "/home/mburu/Master_Thesis/master-thesis-da/DNN_Trial/models/tree_models.py", line 51, in fit
    self.model = xgb.train(self.params, train, num_boost_round=self.args.epochs, evals=eval_list, 
  File "/home/mburu/.local/lib/python3.8/site-packages/xgboost/core.py", line 738, in inner_f
    return func(**kwargs)
  File "/home/mburu/.local/lib/python3.8/site-packages/xgboost/training.py", line 176, in train
    bst = cb_container.before_training(bst)
  File "/home/mburu/.local/lib/python3.8/site-packages/xgboost/callback.py", line 179, in before_training
    model = c.before_training(model=model)
  File "/home/mburu/.local/lib/python3.8/site-packages/xgboost/callback.py", line 374, in before_training
    self.starting_round = model.num_boosted_rounds()
  File "/home/mburu/.local/lib/python3.8/site-packages/xgboost/core.py", line 2755, in num_boosted_rounds
    _check_call(_LIB.XGBoosterBoostedRounds(self.handle, ctypes.byref(rounds)))
  File "/home/mburu/.local/lib/python3.8/site-packages/xgboost/core.py", line 296, in _check_call
    raise XGBoostError(py_str(_LIB.XGBGetLastError()))
xgboost.core.XGBoostError: [09:57:56] /workspace/src/c_api/../common/common.h:174: XGBoost version not compiled with GPU support.
Stack trace:
  [bt] (0) /home/mburu/.local/lib/python3.8/site-packages/xgboost/lib/libxgboost.so(+0x170a4e) [0x7fb442f2ba4e]
  [bt] (1) /home/mburu/.local/lib/python3.8/site-packages/xgboost/lib/libxgboost.so(+0x170d11) [0x7fb442f2bd11]
  [bt] (2) /home/mburu/.local/lib/python3.8/site-packages/xgboost/lib/libxgboost.so(+0x4db3df) [0x7fb4432963df]
  [bt] (3) /home/mburu/.local/lib/python3.8/site-packages/xgboost/lib/libxgboost.so(+0x52f130) [0x7fb4432ea130]
  [bt] (4) /home/mburu/.local/lib/python3.8/site-packages/xgboost/lib/libxgboost.so(XGBoosterBoostedRounds+0x1d) [0x7fb442e424dd]
  [bt] (5) /home/mburu/miniconda3/envs/TabSurvey2/lib/python3.8/lib-dynload/../../libffi.so.8(+0xa052) [0x7fb45d0d7052]
  [bt] (6) /home/mburu/miniconda3/envs/TabSurvey2/lib/python3.8/lib-dynload/../../libffi.so.8(+0x8925) [0x7fb45d0d5925]
  [bt] (7) /home/mburu/miniconda3/envs/TabSurvey2/lib/python3.8/lib-dynload/../../libffi.so.8(ffi_call+0xde) [0x7fb45d0d606e]
  [bt] (8) /home/mburu/miniconda3/envs/TabSurvey2/lib/python3.8/lib-dynload/_ctypes.cpython-38-x86_64-linux-gnu.so(_ctypes_callproc+0x31f) [0x7fb45d0f14af]


srun: error: stud-000: task 0: Exited with exit code 1
