[I 2025-01-23 09:55:53,804] Using an existing study with name 'XGBoost_House_Prices_Nominal' instead of creating a new one.
[W 2025-01-23 09:55:54,121] Trial 101 failed with parameters: {'max_depth': 4, 'alpha': 5.023849955282712e-05, 'lambda': 0.0183315186108122, 'eta': 0.246907996586258} because of the following error: XGBoostError('[09:55:54] /workspace/src/c_api/../common/common.h:174: XGBoost version not compiled with GPU support.\nStack trace:\n  [bt] (0) /home/mburu/.local/lib/python3.8/site-packages/xgboost/lib/libxgboost.so(+0x170a4e) [0x7fb08af6ca4e]\n  [bt] (1) /home/mburu/.local/lib/python3.8/site-packages/xgboost/lib/libxgboost.so(+0x170d11) [0x7fb08af6cd11]\n  [bt] (2) /home/mburu/.local/lib/python3.8/site-packages/xgboost/lib/libxgboost.so(+0x4db3df) [0x7fb08b2d73df]\n  [bt] (3) /home/mburu/.local/lib/python3.8/site-packages/xgboost/lib/libxgboost.so(+0x52f130) [0x7fb08b32b130]\n  [bt] (4) /home/mburu/.local/lib/python3.8/site-packages/xgboost/lib/libxgboost.so(XGBoosterBoostedRounds+0x1d) [0x7fb08ae834dd]\n  [bt] (5) /home/mburu/miniconda3/envs/TabSurvey2/lib/python3.8/lib-dynload/../../libffi.so.8(+0xa052) [0x7fb0a4d83052]\n  [bt] (6) /home/mburu/miniconda3/envs/TabSurvey2/lib/python3.8/lib-dynload/../../libffi.so.8(+0x8925) [0x7fb0a4d81925]\n  [bt] (7) /home/mburu/miniconda3/envs/TabSurvey2/lib/python3.8/lib-dynload/../../libffi.so.8(ffi_call+0xde) [0x7fb0a4d8206e]\n  [bt] (8) /home/mburu/miniconda3/envs/TabSurvey2/lib/python3.8/lib-dynload/_ctypes.cpython-38-x86_64-linux-gnu.so(_ctypes_callproc+0x31f) [0x7fb0a4d9d4af]\n\n').
Traceback (most recent call last):
  File "/home/mburu/.local/lib/python3.8/site-packages/optuna/study/_optimize.py", line 197, in _run_trial
    value_or_values = func(trial)
  File "train.py", line 134, in __call__
    sc, time = cross_validation(model, self.X, self.y, self.args, visual=False)
  File "train.py", line 46, in cross_validation
    loss_history, val_loss_history = curr_model.fit(X_train, y_train, X_test, y_test)  # X_val, y_val)
  File "/home/mburu/Master_Thesis/master-thesis-da/DNN_Trial/models/tree_models.py", line 51, in fit
    self.model = xgb.train(self.params, train, num_boost_round=self.args.epochs, evals=eval_list,
  File "/home/mburu/.local/lib/python3.8/site-packages/xgboost/core.py", line 738, in inner_f
    return func(**kwargs)
  File "/home/mburu/.local/lib/python3.8/site-packages/xgboost/training.py", line 176, in train
    bst = cb_container.before_training(bst)
  File "/home/mburu/.local/lib/python3.8/site-packages/xgboost/callback.py", line 179, in before_training
    model = c.before_training(model=model)
  File "/home/mburu/.local/lib/python3.8/site-packages/xgboost/callback.py", line 374, in before_training
    self.starting_round = model.num_boosted_rounds()
  File "/home/mburu/.local/lib/python3.8/site-packages/xgboost/core.py", line 2755, in num_boosted_rounds
    _check_call(_LIB.XGBoosterBoostedRounds(self.handle, ctypes.byref(rounds)))
  File "/home/mburu/.local/lib/python3.8/site-packages/xgboost/core.py", line 296, in _check_call
    raise XGBoostError(py_str(_LIB.XGBGetLastError()))
xgboost.core.XGBoostError: [09:55:54] /workspace/src/c_api/../common/common.h:174: XGBoost version not compiled with GPU support.
Stack trace:
  [bt] (0) /home/mburu/.local/lib/python3.8/site-packages/xgboost/lib/libxgboost.so(+0x170a4e) [0x7fb08af6ca4e]
  [bt] (1) /home/mburu/.local/lib/python3.8/site-packages/xgboost/lib/libxgboost.so(+0x170d11) [0x7fb08af6cd11]
  [bt] (2) /home/mburu/.local/lib/python3.8/site-packages/xgboost/lib/libxgboost.so(+0x4db3df) [0x7fb08b2d73df]
  [bt] (3) /home/mburu/.local/lib/python3.8/site-packages/xgboost/lib/libxgboost.so(+0x52f130) [0x7fb08b32b130]
  [bt] (4) /home/mburu/.local/lib/python3.8/site-packages/xgboost/lib/libxgboost.so(XGBoosterBoostedRounds+0x1d) [0x7fb08ae834dd]
  [bt] (5) /home/mburu/miniconda3/envs/TabSurvey2/lib/python3.8/lib-dynload/../../libffi.so.8(+0xa052) [0x7fb0a4d83052]
  [bt] (6) /home/mburu/miniconda3/envs/TabSurvey2/lib/python3.8/lib-dynload/../../libffi.so.8(+0x8925) [0x7fb0a4d81925]
  [bt] (7) /home/mburu/miniconda3/envs/TabSurvey2/lib/python3.8/lib-dynload/../../libffi.so.8(ffi_call+0xde) [0x7fb0a4d8206e]
  [bt] (8) /home/mburu/miniconda3/envs/TabSurvey2/lib/python3.8/lib-dynload/_ctypes.cpython-38-x86_64-linux-gnu.so(_ctypes_callproc+0x31f) [0x7fb0a4d9d4af]


[W 2025-01-23 09:55:54,148] Trial 101 failed with value None.
Traceback (most recent call last):
  File "train.py", line 185, in <module>
    main(arguments)
  File "train.py", line 156, in main
    study.optimize(Objective(args, model_name, X, y), n_trials=args.n_trials)
  File "/home/mburu/.local/lib/python3.8/site-packages/optuna/study/study.py", line 475, in optimize
    _optimize(
  File "/home/mburu/.local/lib/python3.8/site-packages/optuna/study/_optimize.py", line 63, in _optimize
    _optimize_sequential(
  File "/home/mburu/.local/lib/python3.8/site-packages/optuna/study/_optimize.py", line 160, in _optimize_sequential
    frozen_trial = _run_trial(study, func, catch)
  File "/home/mburu/.local/lib/python3.8/site-packages/optuna/study/_optimize.py", line 248, in _run_trial
    raise func_err
  File "/home/mburu/.local/lib/python3.8/site-packages/optuna/study/_optimize.py", line 197, in _run_trial
    value_or_values = func(trial)
  File "train.py", line 134, in __call__
    sc, time = cross_validation(model, self.X, self.y, self.args, visual=False)
  File "train.py", line 46, in cross_validation
    loss_history, val_loss_history = curr_model.fit(X_train, y_train, X_test, y_test)  # X_val, y_val)
  File "/home/mburu/Master_Thesis/master-thesis-da/DNN_Trial/models/tree_models.py", line 51, in fit
    self.model = xgb.train(self.params, train, num_boost_round=self.args.epochs, evals=eval_list, 
  File "/home/mburu/.local/lib/python3.8/site-packages/xgboost/core.py", line 738, in inner_f
    return func(**kwargs)
  File "/home/mburu/.local/lib/python3.8/site-packages/xgboost/training.py", line 176, in train
    bst = cb_container.before_training(bst)
  File "/home/mburu/.local/lib/python3.8/site-packages/xgboost/callback.py", line 179, in before_training
    model = c.before_training(model=model)
  File "/home/mburu/.local/lib/python3.8/site-packages/xgboost/callback.py", line 374, in before_training
    self.starting_round = model.num_boosted_rounds()
  File "/home/mburu/.local/lib/python3.8/site-packages/xgboost/core.py", line 2755, in num_boosted_rounds
    _check_call(_LIB.XGBoosterBoostedRounds(self.handle, ctypes.byref(rounds)))
  File "/home/mburu/.local/lib/python3.8/site-packages/xgboost/core.py", line 296, in _check_call
    raise XGBoostError(py_str(_LIB.XGBGetLastError()))
xgboost.core.XGBoostError: [09:55:54] /workspace/src/c_api/../common/common.h:174: XGBoost version not compiled with GPU support.
Stack trace:
  [bt] (0) /home/mburu/.local/lib/python3.8/site-packages/xgboost/lib/libxgboost.so(+0x170a4e) [0x7fb08af6ca4e]
  [bt] (1) /home/mburu/.local/lib/python3.8/site-packages/xgboost/lib/libxgboost.so(+0x170d11) [0x7fb08af6cd11]
  [bt] (2) /home/mburu/.local/lib/python3.8/site-packages/xgboost/lib/libxgboost.so(+0x4db3df) [0x7fb08b2d73df]
  [bt] (3) /home/mburu/.local/lib/python3.8/site-packages/xgboost/lib/libxgboost.so(+0x52f130) [0x7fb08b32b130]
  [bt] (4) /home/mburu/.local/lib/python3.8/site-packages/xgboost/lib/libxgboost.so(XGBoosterBoostedRounds+0x1d) [0x7fb08ae834dd]
  [bt] (5) /home/mburu/miniconda3/envs/TabSurvey2/lib/python3.8/lib-dynload/../../libffi.so.8(+0xa052) [0x7fb0a4d83052]
  [bt] (6) /home/mburu/miniconda3/envs/TabSurvey2/lib/python3.8/lib-dynload/../../libffi.so.8(+0x8925) [0x7fb0a4d81925]
  [bt] (7) /home/mburu/miniconda3/envs/TabSurvey2/lib/python3.8/lib-dynload/../../libffi.so.8(ffi_call+0xde) [0x7fb0a4d8206e]
  [bt] (8) /home/mburu/miniconda3/envs/TabSurvey2/lib/python3.8/lib-dynload/_ctypes.cpython-38-x86_64-linux-gnu.so(_ctypes_callproc+0x31f) [0x7fb0a4d9d4af]


srun: error: stud-000: task 0: Exited with exit code 1
