Traceback (most recent call last):
  File "/usr/lib/python3.8/urllib/request.py", line 1354, in do_open
    h.request(req.get_method(), req.selector, req.data, headers,
  File "/usr/lib/python3.8/http/client.py", line 1256, in request
    self._send_request(method, url, body, headers, encode_chunked)
  File "/usr/lib/python3.8/http/client.py", line 1302, in _send_request
    self.endheaders(body, encode_chunked=encode_chunked)
  File "/usr/lib/python3.8/http/client.py", line 1251, in endheaders
    self._send_output(message_body, encode_chunked=encode_chunked)
  File "/usr/lib/python3.8/http/client.py", line 1011, in _send_output
    self.send(msg)
  File "/usr/lib/python3.8/http/client.py", line 951, in send
    self.connect()
  File "/usr/lib/python3.8/http/client.py", line 1418, in connect
    super().connect()
  File "/usr/lib/python3.8/http/client.py", line 922, in connect
    self.sock = self._create_connection(
  File "/usr/lib/python3.8/socket.py", line 787, in create_connection
    for res in getaddrinfo(host, port, 0, SOCK_STREAM):
  File "/usr/lib/python3.8/socket.py", line 918, in getaddrinfo
    for res in _socket.getaddrinfo(host, port, family, type, proto, flags):
socket.gaierror: [Errno -3] Temporary failure in name resolution

During handling of the above exception, another exception occurred:

Traceback (most recent call last):
  File "train.py", line 149, in <module>
    main_once(arguments)
  File "train.py", line 126, in main_once
    X, y = load_data(args)
  File "/home/mburu/Master_Thesis/master-thesis-da/DNN_Trial/utils/load_data.py", line 20, in load_data
    X, y = sklearn.datasets.fetch_california_housing(return_X_y=True)
  File "/home/mburu/.local/lib/python3.8/site-packages/sklearn/utils/_param_validation.py", line 214, in wrapper
    return func(*args, **kwargs)
  File "/home/mburu/.local/lib/python3.8/site-packages/sklearn/datasets/_california_housing.py", line 148, in fetch_california_housing
    archive_path = _fetch_remote(ARCHIVE, dirname=data_home)
  File "/home/mburu/.local/lib/python3.8/site-packages/sklearn/datasets/_base.py", line 1391, in _fetch_remote
    urlretrieve(remote.url, file_path)
  File "/usr/lib/python3.8/urllib/request.py", line 247, in urlretrieve
    with contextlib.closing(urlopen(url, data)) as fp:
  File "/usr/lib/python3.8/urllib/request.py", line 222, in urlopen
    return opener.open(url, data, timeout)
  File "/usr/lib/python3.8/urllib/request.py", line 525, in open
    response = self._open(req, data)
  File "/usr/lib/python3.8/urllib/request.py", line 542, in _open
    result = self._call_chain(self.handle_open, protocol, protocol +
  File "/usr/lib/python3.8/urllib/request.py", line 502, in _call_chain
    result = func(*args)
  File "/usr/lib/python3.8/urllib/request.py", line 1397, in https_open
    return self.do_open(http.client.HTTPSConnection, req,
  File "/usr/lib/python3.8/urllib/request.py", line 1357, in do_open
    raise URLError(err)
urllib.error.URLError: <urlopen error [Errno -3] Temporary failure in name resolution>
srun: error: stud-000: task 0: Exited with exit code 1
